========================================= Test 1 =========================================
0
1
2
3
4
========================================= Test 2 =========================================
>>> Tested
========================================= Test 5 =========================================
!!!!!!!!!!!!!!!!!!!!!!!!!!!!!!!!!!!!!!!!! ERRORS !!!!!!!!!!!!!!!!!!!!!!!!!!!!!!!!!!!!!!!!!

Traceback (most recent call last):
  File "C:\Users\JoelT\OneDrive\Data\Computer\Programing\python_tasks_autocorrector\test/test_battery_of_tests.py", line 242, in main
    test(internal_spec, internal_module)
  File "C:\Users\JoelT\OneDrive\Data\Computer\Programing\python_tasks_autocorrector\test/test_battery_of_tests.py", line 171, in test_5
    internal_module.testOtherException()
  File "C:\Users\JoelT\OneDrive\Data\Computer\Programing\python_tasks_autocorrector\test/test_submission.py", line 20, in testOtherException
    raise UserWarning("This is a warning")
UserWarning: This is a warning

!!!!!!!!!!!!!!!!!!!!!!!!!!!!!!!!!!!!!!!!!!!!!!!!!!!!!!!!!!!!!!!!!!!!!!!!!!!!!!!!!!!!!!!!!!
